Workbook

Sheet Dashboard
A1: BURGER KING (RBI SEGMENT) - 3-STATEMENT MODEL & QSR DASHBOARD
A2: USD millions unless noted | 2024A - 2028E | Fully integrated & balanced (BS check = 0)
A4: HEADLINE KPIs
A5: Metric | B5: 2024A | C5: 2028E | D5: '24-'28
A6: System-Wide Sales ($M) | B6: =UnitEcon!B12 -> 26325 | C6: =UnitEcon!F12 -> 31293.768 | D6: =(C6/B6)^(1/4)-1 -> 0.044173
A7: Total Revenue ($M) | B7: =IS!B7 -> 1999.08 | C7: =IS!F7 -> 2208.3739 | D7: =(C7/B7)^(1/4)-1 -> 0.025205
A8: Adjusted EBITDA ($M) | B8: =IS!B13 -> 1064.9556 | C8: =IS!F13 -> 1264.2271 | D8: =(C8/B8)^(1/4)-1 -> 0.043815
A9: Net Income ($M) | B9: =IS!B20 -> 549.05853 | C9: =IS!F20 -> 728.16251 | D9: =(C9/B9)^(1/4)-1 -> 0.07313
A10: Free Cash Flow ($M) | B10: =CF!B5+CF!B6 -> 552.95528 | C10: =CF!F5+CF!F6 -> 720.46736 | D10: =(C10/B10)^(1/4)-1 -> 0.068393
A11: Total Units | B11: =UnitEcon!B3 -> 19500 | C11: =UnitEcon!F3 -> 20696.589 | D11: =(C11/B11)^(1/4)-1 -> 0.015
A12: EBITDA Margin % | B12: =IS!B14 -> 0.532723 | C12: =IS!F14 -> 0.57247 | D12: =C12-B12 -> 0.039747
A13: Net Debt / EBITDA (x) | B13: =(BS!B17+BS!B20-BS!B3)/IS!B13 -> 3.756025 | C13: =(BS!F17+BS!F20-BS!F3)/IS!F13 -> 1.916445 | D13: =C13-B13 -> -1.83958
A14: ROE % | B14: =IS!B20/BS!B30 -> 0.145639 | C14: =IS!F20/BS!F30 -> 0.135839 | D14: =C14-B14 -> -0.0098
A16: VISUAL TRENDS (each █ scaled to series max)
A17: Total Revenue ($M)
A18: 2024 | B18: =IS!B7 -> 1999.08 | C18: =REPT("█",ROUND((IS!B7)/88.33,0)) -> ███████████████████████
A19: 2025 | B19: =IS!C7 -> 2054.843 | C19: =REPT("█",ROUND((IS!C7)/88.33,0)) -> ███████████████████████
A20: 2026 | B20: =IS!D7 -> 2102.2457 | C20: =REPT("█",ROUND((IS!D7)/88.33,0)) -> ████████████████████████
A21: 2027 | B21: =IS!E7 -> 2154.4514 | C21: =REPT("█",ROUND((IS!E7)/88.33,0)) -> ████████████████████████
A22: 2028 | B22: =IS!F7 -> 2208.3739 | C22: =REPT("█",ROUND((IS!F7)/88.33,0)) -> █████████████████████████
A23: Adjusted EBITDA ($M)
A24: 2024 | B24: =IS!B13 -> 1064.9556 | C24: =REPT("█",ROUND((IS!B13)/50.57,0)) -> █████████████████████
A25: 2025 | B25: =IS!C13 -> 1118.2951 | C25: =REPT("█",ROUND((IS!C13)/50.57,0)) -> ██████████████████████
A26: 2026 | B26: =IS!D13 -> 1168.6466 | C26: =REPT("█",ROUND((IS!D13)/50.57,0)) -> ███████████████████████
A27: 2027 | B27: =IS!E13 -> 1215.4931 | C27: =REPT("█",ROUND((IS!E13)/50.57,0)) -> ████████████████████████
A28: 2028 | B28: =IS!F13 -> 1264.2271 | C28: =REPT("█",ROUND((IS!F13)/50.57,0)) -> █████████████████████████
A29: System-Wide Sales ($M)
A30: 2024 | B30: =UnitEcon!B12 -> 26325 | C30: =REPT("█",ROUND((UnitEcon!B12)/1251.75,0)) -> █████████████████████
A31: 2025 | B31: =UnitEcon!C12 -> 27655.071 | C31: =REPT("█",ROUND((UnitEcon!C12)/1251.75,0)) -> ██████████████████████
A32: 2026 | B32: =UnitEcon!D12 -> 28911.994 | C32: =REPT("█",ROUND((UnitEcon!D12)/1251.75,0)) -> ███████████████████████
A33: 2027 | B33: =UnitEcon!E12 -> 30079.315 | C33: =REPT("█",ROUND((UnitEcon!E12)/1251.75,0)) -> ████████████████████████
A34: 2028 | B34: =UnitEcon!F12 -> 31293.768 | C34: =REPT("█",ROUND((UnitEcon!F12)/1251.75,0)) -> █████████████████████████
A35: Free Cash Flow ($M)
A36: 2024 | B36: =CF!B5+CF!B6 -> 552.95528 | C36: =REPT("█",ROUND((CF!B5+CF!B6)/28.82,0)) -> ███████████████████
A37: 2025 | B37: =CF!C5+CF!C6 -> 597.58831 | C37: =REPT("█",ROUND((CF!C5+CF!C6)/28.82,0)) -> █████████████████████
A38: 2026 | B38: =CF!D5+CF!D6 -> 639.92102 | C38: =REPT("█",ROUND((CF!D5+CF!D6)/28.82,0)) -> ██████████████████████
A39: 2027 | B39: =CF!E5+CF!E6 -> 679.52892 | C39: =REPT("█",ROUND((CF!E5+CF!E6)/28.82,0)) -> ████████████████████████
A40: 2028 | B40: =CF!F5+CF!F6 -> 720.46736 | C40: =REPT("█",ROUND((CF!F5+CF!F6)/28.82,0)) -> █████████████████████████
A41: Total Units
A42: 2024 | B42: =UnitEcon!B3 -> 19500 | C42: =REPT("█",ROUND((UnitEcon!B3)/827.86,0)) -> ████████████████████████
...

Sheet Assumptions
A1: ASSUMPTIONS (USD millions unless noted) | B1: 2024 | C1: 2025 | D1: 2026 | E1: 2027 | F1: 2028
A2: UNIT & SALES DRIVERS
A3: Same-Store Sales (SSS) % | B3: 0.03 | C3: 0.035 | D3: 0.03 | E3: 0.025 | F3: 0.025
A4: Net Unit Growth % | C4: 0.015 | D4: 0.015 | E4: 0.015 | F4: 0.015
A5: Gross Openings (% beg. units) | B5: 0.03 | C5: 0.03 | D5: 0.03 | E5: 0.03 | F5: 0.03
A6: Closures (% beg. units) | B6: 0.015 | C6: 0.015 | D6: 0.015 | E6: 0.015 | F6: 0.015
A7: Company-Operated Units (#) | B7: 300 | C7: 270 | D7: 240 | E7: 220 | F7: 200
A8: AUV - System ($M / unit) | B8: 1.35 | C8: =B8*(1+C3) -> 1.39725 | D8: =C8*(1+D3) -> 1.439167 | E8: =D8*(1+E3) -> 1.475147 | F8: =E8*(1+F3) -> 1.512025
A9: PRICING / FRANCHISE ECONOMICS
A10: Royalty Rate % | B10: 0.045 | C10: 0.045 | D10: 0.045 | E10: 0.045 | F10: 0.045
A11: Property Revenue Rate % | B11: 0.015 | C11: 0.015 | D11: 0.015 | E11: 0.015 | F11: 0.015
A12: Franchise Fees & Other Rate % | B12: 0.0015 | C12: 0.0015 | D12: 0.0015 | E12: 0.0015 | F12: 0.0015
A13: Cost of Company Sales % | B13: 0.82 | C13: 0.82 | D13: 0.82 | E13: 0.82 | F13: 0.82
A14: Franchise & Property Cost % | B14: 0.22 | C14: 0.22 | D14: 0.22 | E14: 0.22 | F14: 0.22
A15: G&A % of Revenue | B15: 0.13 | C15: 0.13 | D15: 0.13 | E15: 0.13 | F15: 0.13
A16: CAPITAL & FINANCING
A17: Depreciation & Amort. % Rev | B17: 0.06 | C17: 0.06 | D17: 0.06 | E17: 0.06 | F17: 0.06
A18: Tax Rate % | B18: 0.21 | C18: 0.21 | D18: 0.21 | E18: 0.21 | F18: 0.21
A19: Interest Rate % | B19: 0.05 | C19: 0.05 | D19: 0.05 | E19: 0.05 | F19: 0.05
A20: CapEx per Store ($) | B20: 6000 | C20: 6200 | D20: 6400 | E20: 6600 | F20: 6800
A21: LT Debt Repayment ($M) | B21: 200 | C21: 200 | D21: 200 | E21: 200 | F21: 200
A22: Dividend Payout % | B22: 0.4 | C22: 0.4 | D22: 0.4 | E22: 0.4 | F22: 0.4
A23: Shares Outstanding (M) | B23: 320 | C23: 320 | D23: 320 | E23: 320 | F23: 320

Sheet UnitEcon
A1: UNIT ECONOMICS (store-level) | B1: 2024 | C1: 2025 | D1: 2026 | E1: 2027 | F1: 2028
A2: UNIT COUNTS
A3: Total Units (Ending) | B3: 19500 | C3: =B3*(1+Assumptions!C4) -> 19792.5 | D3: =C3*(1+Assumptions!D4) -> 20089.388 | E3: =D3*(1+Assumptions!E4) -> 20390.728 | F3: =E3*(1+Assumptions!F4) -> 20696.589
A4: Net New Units | B4: 288 | C4: =C3-B3 -> 292.5 | D4: =D3-C3 -> 296.8875 | E4: =E3-D3 -> 301.34081 | F4: =F3-E3 -> 305.86093
A5: Gross Openings | B5: 576 | C5: =B3*Assumptions!C5 -> 585 | D5: =C3*Assumptions!D5 -> 593.775 | E5: =D3*Assumptions!E5 -> 602.68163 | F5: =E3*Assumptions!F5 -> 611.72185
A6: Closures | B6: 288 | C6: =B3*Assumptions!C6 -> 292.5 | D6: =C3*Assumptions!D6 -> 296.8875 | E6: =D3*Assumptions!E6 -> 301.34081 | F6: =E3*Assumptions!F6 -> 305.86093
A7: Company-Operated Units | B7: =Assumptions!B7 -> 300 | C7: =Assumptions!C7 -> 270 | D7: =Assumptions!D7 -> 240 | E7: =Assumptions!E7 -> 220 | F7: =Assumptions!F7 -> 200
A8: Franchised Units | B8: =B3-B7 -> 19200 | C8: =C3-C7 -> 19522.5 | D8: =D3-D7 -> 19849.388 | E8: =E3-E7 -> 20170.728 | F8: =F3-F7 -> 20496.589
A9: % Franchised | B9: =B8/B3 -> 0.984615 | C9: =C8/C3 -> 0.986358 | D9: =D8/D3 -> 0.988053 | E9: =E8/E3 -> 0.989211 | F9: =F8/F3 -> 0.990337
A10: UNIT VOLUMES & SYSTEM SALES
A11: AUV - System ($M / unit) | B11: =Assumptions!B8 -> 1.35 | C11: =Assumptions!C8 -> 1.39725 | D11: =Assumptions!D8 -> 1.439167 | E11: =Assumptions!E8 -> 1.475147 | F11: =Assumptions!F8 -> 1.512025
A12: System-Wide Sales ($M) | B12: =B3*B11 -> 26325 | C12: =C3*C11 -> 27655.071 | D12: =D3*D11 -> 28911.994 | E12: =E3*E11 -> 30079.315 | F12: =F3*F11 -> 31293.768
A13: Company Restaurant Sales ($M) | B13: =B7*B11 -> 405 | C13: =C7*C11 -> 377.2575 | D13: =D7*D11 -> 345.4002 | E13: =E7*E11 -> 324.53227 | F13: =F7*F11 -> 302.40507
A14: Franchised System Sales ($M) | B14: =B8*B11 -> 25920 | C14: =C8*C11 -> 27277.813 | D14: =D8*D11 -> 28566.593 | E14: =E8*E11 -> 29754.783 | F14: =F8*F11 -> 30991.363
A15: System Sales Growth % | C15: =C12/B12-1 -> 0.050525 | D15: =D12/C12-1 -> 0.04545 | E15: =E12/D12-1 -> 0.040375 | F15: =F12/E12-1 -> 0.040375
A16: STORE-LEVEL (4-WALL) P&L
A17: Avg Sales / Company Unit ($M) | B17: =B13/B7 -> 1.35 | C17: =C13/C7 -> 1.39725 | D17: =D13/D7 -> 1.439167 | E17: =E13/E7 -> 1.475147 | F17: =F13/F7 -> 1.512025
A18: Restaurant-Level Costs ($M) | B18: =B13*Assumptions!B13 -> 332.1 | C18: =C13*Assumptions!C13 -> 309.35115 | D18: =D13*Assumptions!D13 -> 283.22816 | E18: =E13*Assumptions!E13 -> 266.11646 | F18: =F13*Assumptions!F13 -> 247.97216
A19: Restaurant-Level EBITDA ($M) | B19: =B13-B18 -> 72.9 | C19: =C13-C18 -> 67.90635 | D19: =D13-D18 -> 62.172036 | E19: =E13-E18 -> 58.415809 | F19: =F13-F18 -> 54.432913
A20: Restaurant-Level Margin % | B20: =B19/B13 -> 0.18 | C20: =C19/C13 -> 0.18 | D20: =D19/D13 -> 0.18 | E20: =E19/E13 -> 0.18 | F20: =F19/F13 -> 0.18

Sheet IS
A1: INCOME STATEMENT (USD millions) | B1: 2024 | C1: 2025 | D1: 2026 | E1: 2027 | F1: 2028
A2: REVENUE
A3: Company Restaurant Sales | B3: =UnitEcon!B13 -> 405 | C3: =UnitEcon!C13 -> 377.2575 | D3: =UnitEcon!D13 -> 345.4002 | E3: =UnitEcon!E13 -> 324.53227 | F3: =UnitEcon!F13 -> 302.40507
A4: Franchise Royalties | B4: =UnitEcon!B14*Assumptions!B10 -> 1166.4 | C4: =UnitEcon!C14*Assumptions!C10 -> 1227.5016 | D4: =UnitEcon!D14*Assumptions!D10 -> 1285.4967 | E4: =UnitEcon!E14*Assumptions!E10 -> 1338.9652 | F4: =UnitEcon!F14*Assumptions!F10 -> 1394.6113
A5: Property Revenue | B5: =UnitEcon!B14*Assumptions!B11 -> 388.8 | C5: =UnitEcon!C14*Assumptions!C11 -> 409.1672 | D5: =UnitEcon!D14*Assumptions!D11 -> 428.4989 | E5: =UnitEcon!E14*Assumptions!E11 -> 446.32175 | F5: =UnitEcon!F14*Assumptions!F11 -> 464.87044
A6: Franchise Fees & Other | B6: =UnitEcon!B14*Assumptions!B12 -> 38.88 | C6: =UnitEcon!C14*Assumptions!C12 -> 40.91672 | D6: =UnitEcon!D14*Assumptions!D12 -> 42.84989 | E6: =UnitEcon!E14*Assumptions!E12 -> 44.632175 | F6: =UnitEcon!F14*Assumptions!F12 -> 46.487044
A7: Total Revenue | B7: =SUM(B3:B6) -> 1999.08 | C7: =SUM(C3:C6) -> 2054.843 | D7: =SUM(D3:D6) -> 2102.2457 | E7: =SUM(E3:E6) -> 2154.4514 | F7: =SUM(F3:F6) -> 2208.3739
A8: OPERATING COSTS
A9: Cost of Company Restaurant Sales | B9: =B3*Assumptions!B13 -> 332.1 | C9: =C3*Assumptions!C13 -> 309.35115 | D9: =D3*Assumptions!D13 -> 283.22816 | E9: =E3*Assumptions!E13 -> 266.11646 | F9: =F3*Assumptions!F13 -> 247.97216
A10: Franchise & Property Expenses | B10: =(B4+B5)*Assumptions!B14 -> 342.144 | C10: =(C4+C5)*Assumptions!C14 -> 360.06713 | D10: =(D4+D5)*Assumptions!D14 -> 377.07903 | E10: =(E4+E5)*Assumptions!E14 -> 392.76314 | F10: =(F4+F5)*Assumptions!F14 -> 409.08599
A11: General & Administrative (G&A) | B11: =B7*Assumptions!B15 -> 259.8804 | C11: =C7*Assumptions!C15 -> 267.12959 | D11: =D7*Assumptions!D15 -> 273.29194 | E11: =E7*Assumptions!E15 -> 280.07869 | F11: =F7*Assumptions!F15 -> 287.0886
A12: Total Operating Costs | B12: =SUM(B9:B11) -> 934.1244 | C12: =SUM(C9:C11) -> 936.54787 | D12: =SUM(D9:D11) -> 933.59914 | E12: =SUM(E9:E11) -> 938.95829 | F12: =SUM(F9:F11) -> 944.14675
A13: Adjusted EBITDA | B13: =B7-B12 -> 1064.9556 | C13: =C7-C12 -> 1118.2951 | D13: =D7-D12 -> 1168.6466 | E13: =E7-E12 -> 1215.4931 | F13: =F7-F12 -> 1264.2271
A14: EBITDA Margin % | B14: =B13/B7 -> 0.532723 | C14: =C13/C7 -> 0.544224 | D14: =D13/D7 -> 0.555904 | E14: =E13/E7 -> 0.564178 | F14: =F13/F7 -> 0.57247
A15: Depreciation & Amortization | B15: =B7*Assumptions!B17 -> 119.9448 | C15: =C7*Assumptions!C17 -> 123.29058 | D15: =D7*Assumptions!D17 -> 126.13474 | E15: =E7*Assumptions!E17 -> 129.26709 | F15: =F7*Assumptions!F17 -> 132.50243
A16: EBIT | B16: =B13-B15 -> 945.0108 | C16: =C13-C15 -> 995.00455 | D16: =D13-D15 -> 1042.5118 | E16: =E13-E15 -> 1086.2261 | F16: =F13-F15 -> 1131.7247
A17: Interest Expense | B17: =Assumptions!B19*(BS!B17+BS!B20) -> 250 | C17: =Assumptions!C19*(BS!C17+BS!C20) -> 240 | D17: =Assumptions!D19*(BS!D17+BS!D20) -> 230 | E17: =Assumptions!E19*(BS!E17+BS!E20) -> 220 | F17: =Assumptions!F19*(BS!F17+BS!F20) -> 210
A18: Pre-Tax Income | B18: =B16-B17 -> 695.0108 | C18: =C16-C17 -> 755.00455 | D18: =D16-D17 -> 812.51181 | E18: =E16-E17 -> 866.22606 | F18: =F16-F17 -> 921.72469
A19: Taxes | B19: =B18*Assumptions!B18 -> 145.95227 | C19: =C18*Assumptions!C18 -> 158.55096 | D19: =D18*Assumptions!D18 -> 170.62748 | E19: =E18*Assumptions!E18 -> 181.90747 | F19: =F18*Assumptions!F18 -> 193.56218
A20: Net Income | B20: =B18-B19 -> 549.05853 | C20: =C18-C19 -> 596.4536 | D20: =D18-D19 -> 641.88433 | E20: =E18-E19 -> 684.31859 | F20: =F18-F19 -> 728.16251
A21: EPS ($) | B21: =B20/Assumptions!B23 -> 1.715808 | C21: =C20/Assumptions!C23 -> 1.863917 | D21: =D20/Assumptions!D23 -> 2.005889 | E21: =E20/Assumptions!E23 -> 2.138496 | F21: =F20/Assumptions!F23 -> 2.275508

Sheet BS
A1: BALANCE SHEET (USD millions) | B1: 2024 | C1: 2025 | D1: 2026 | E1: 2027 | F1: 2028
A2: ASSETS
A3: Cash | B3: =CF!B13 -> 1000 | C3: =CF!C13 -> 1159.0069 | D3: =CF!D13 -> 1342.1742 | E3: =CF!E13 -> 1547.9756 | F3: =CF!F13 -> 1777.178
A4: Accounts Receivable | B4: 139.9356 | C4: =B4*IS!C7/IS!B7 -> 143.83901 | D4: =C4*IS!D7/IS!C7 -> 147.1572 | E4: =D4*IS!E7/IS!D7 -> 150.8116 | F4: =E4*IS!F7/IS!E7 -> 154.58617
A5: Inventory | B5: 19.9908 | C5: =B5*IS!C7/IS!B7 -> 20.54843 | D5: =C5*IS!D7/IS!C7 -> 21.022457 | E5: =D5*IS!E7/IS!D7 -> 21.544514 | F5: =E5*IS!F7/IS!E7 -> 22.083739
A6: Prepaid Expenses | B6: 39.9816 | C6: =B6*IS!C7/IS!B7 -> 41.09686 | D6: =C6*IS!D7/IS!C7 -> 42.044914 | E6: =D6*IS!E7/IS!D7 -> 43.089029 | F6: =E6*IS!F7/IS!E7 -> 44.167477
A7: Total Current Assets | B7: =SUM(B3:B6) -> 1199.908 | C7: =SUM(C3:C6) -> 1364.4912 | D7: =SUM(D3:D6) -> 1552.3987 | E7: =SUM(E3:E6) -> 1763.4208 | F7: =SUM(F3:F6) -> 1998.0154
A8: PP&E | B8: 1500 | C8: =B8+Assumptions!C20*UnitEcon!C3/1000000-IS!C15 -> 1499.4229 | D8: =C8+Assumptions!D20*UnitEcon!D3/1000000-IS!D15 -> 1501.8603 | E8: =D8+Assumptions!E20*UnitEcon!E3/1000000-IS!E15 -> 1507.172 | F8: =E8+Assumptions!F20*UnitEcon!F3/1000000-IS!F15 -> 1515.4064
A9: Right-of-Use Assets | B9: 1400 | C9: =B9 -> 1400 | D9: =C9 -> 1400 | E9: =D9 -> 1400 | F9: =E9 -> 1400
A10: Intangibles | B10: 1200 | C10: =B10 -> 1200 | D10: =C10 -> 1200 | E10: =D10 -> 1200 | F10: =E10 -> 1200
A11: Goodwill | B11: 5500 | C11: =B11 -> 5500 | D11: =C11 -> 5500 | E11: =D11 -> 5500 | F11: =E11 -> 5500
A12: Total Non-Current Assets | B12: =SUM(B8:B11) -> 9600 | C12: =SUM(C8:C11) -> 9599.4229 | D12: =SUM(D8:D11) -> 9601.8603 | E12: =SUM(E8:E11) -> 9607.172 | F12: =SUM(F8:F11) -> 9615.4064
A13: TOTAL ASSETS | B13: =B7+B12 -> 10799.908 | C13: =C7+C12 -> 10963.914 | D13: =D7+D12 -> 11154.259 | E13: =E7+E12 -> 11370.593 | F13: =F7+F12 -> 11613.422
A14: LIABILITIES
A15: Accounts Payable | B15: 99.954 | C15: =B15*IS!C7/IS!B7 -> 102.74215 | D15: =C15*IS!D7/IS!C7 -> 105.11228 | E15: =D15*IS!E7/IS!D7 -> 107.72257 | F15: =E15*IS!F7/IS!E7 -> 110.41869
A16: Accrued Expenses | B16: 119.9448 | C16: =B16*IS!C7/IS!B7 -> 123.29058 | D16: =C16*IS!D7/IS!C7 -> 126.13474 | E16: =D16*IS!E7/IS!D7 -> 129.26709 | F16: =E16*IS!F7/IS!E7 -> 132.50243
A17: Short-term Debt | B17: 300 | C17: =B17 -> 300 | D17: =C17 -> 300 | E17: =D17 -> 300 | F17: =E17 -> 300
A18: Current Lease Liability | B18: 160 | C18: =B18 -> 160 | D18: =C18 -> 160 | E18: =D18 -> 160 | F18: =E18 -> 160
A19: Total Current Liabilities | B19: =SUM(B15:B18) -> 679.8988 | C19: =SUM(C15:C18) -> 686.03273 | D19: =SUM(D15:D18) -> 691.24703 | E19: =SUM(E15:E18) -> 696.98966 | F19: =SUM(F15:F18) -> 702.92113
A20: Long-term Debt | B20: 4700 | C20: =B20-Assumptions!C21 -> 4500 | D20: =C20-Assumptions!D21 -> 4300 | E20: =D20-Assumptions!E21 -> 4100 | F20: =E20-Assumptions!F21 -> 3900
A21: Lease Liabilities | B21: 1300 | C21: =B21 -> 1300 | D21: =C21 -> 1300 | E21: =D21 -> 1300 | F21: =E21 -> 1300
A22: Deferred Tax | B22: 350 | C22: =B22 -> 350 | D22: =C22 -> 350 | E22: =D22 -> 350 | F22: =E22 -> 350
A23: Total Non-Current Liabilities | B23: =SUM(B20:B22) -> 6350 | C23: =SUM(C20:C22) -> 6150 | D23: =SUM(D20:D22) -> 5950 | E23: =SUM(E20:E22) -> 5750 | F23: =SUM(F20:F22) -> 5550
A24: TOTAL LIABILITIES | B24: =B19+B23 -> 7029.8988 | C24: =C19+C23 -> 6836.0327 | D24: =D19+D23 -> 6641.247 | E24: =E19+E23 -> 6446.9897 | F24: =F19+F23 -> 6252.9211
A25: EQUITY
A26: Share Capital | B26: 100 | C26: =B26 -> 100 | D26: =C26 -> 100 | E26: =D26 -> 100 | F26: =E26 -> 100
A27: Retained Earnings | B27: 2270.0092 | C27: =B27+IS!C20+CF!C9 -> 2627.8814 | D27: =C27+IS!D20+CF!D9 -> 3013.012 | E27: =D27+IS!E20+CF!E9 -> 3423.6031 | F27: =E27+IS!F20+CF!F9 -> 3860.5006
A28: Additional Paid-In Capital | B28: 2000 | C28: =B28 -> 2000 | D28: =C28 -> 2000 | E28: =D28 -> 2000 | F28: =E28 -> 2000
A29: Treasury Stock | B29: -600 | C29: =B29 -> -600 | D29: =C29 -> -600 | E29: =D29 -> -600 | F29: =E29 -> -600
A30: TOTAL EQUITY | B30: =B26+B27+B28+B29 -> 3770.0092 | C30: =C26+C27+C28+C29 -> 4127.8814 | D30: =D26+D27+D28+D29 -> 4513.012 | E30: =E26+E27+E28+E29 -> 4923.6031 | F30: =F26+F27+F28+F29 -> 5360.5006
A31: TOTAL LIABILITIES + EQUITY | B31: =B24+B30 -> 10799.908 | C31: =C24+C30 -> 10963.914 | D31: =D24+D30 -> 11154.259 | E31: =E24+E30 -> 11370.593 | F31: =F24+F30 -> 11613.422
A32: Balance Check (must = 0) | B32: =B13-B31 -> 0 | C32: =C13-C31 -> 0 | D32: =D13-D31 -> 0 | E32: =E13-E31 -> 0 | F32: =F13-F31 -> 0

Sheet CF
A1: CASH FLOW STATEMENT (USD millions) | B1: 2024 | C1: 2025 | D1: 2026 | E1: 2027 | F1: 2028
A2: Net Income | B2: =IS!B20 -> 549.05853 | C2: =IS!C20 -> 596.4536 | D2: =IS!D20 -> 641.88433 | E2: =IS!E20 -> 684.31859 | F2: =IS!F20 -> 728.16251
A3: Depreciation & Amortization | B3: =IS!B15 -> 119.9448 | C3: =IS!C15 -> 123.29058 | D3: =IS!D15 -> 126.13474 | E3: =IS!E15 -> 129.26709 | F3: =IS!F15 -> 132.50243
A4: Change in Working Capital | B4: 0.951943 | C4: =-((BS!C4-BS!B4)+(BS!C5-BS!B5)+(BS!C6-BS!B6))+((BS!C15-BS!B15)+(BS!C16-BS!B16)) -> 0.55763 | D4: =-((BS!D4-BS!C4)+(BS!D5-BS!C5)+(BS!D6-BS!C6))+((BS!D15-BS!C15)+(BS!D16-BS!C16)) -> 0.474027 | E4: =-((BS!E4-BS!D4)+(BS!E5-BS!D5)+(BS!E6-BS!D6))+((BS!E15-BS!D15)+(BS!E16-BS!D16)) -> 0.522057 | F4: =-((BS!F4-BS!E4)+(BS!F5-BS!E5)+(BS!F6-BS!E6))+((BS!F15-BS!E15)+(BS!F16-BS!E16)) -> 0.539224
A5: Operating Cash Flow | B5: =B2+B3+B4 -> 669.95528 | C5: =C2+C3+C4 -> 720.30181 | D5: =D2+D3+D4 -> 768.4931 | E5: =E2+E3+E4 -> 814.10773 | F5: =F2+F3+F4 -> 861.20416
A6: CapEx | B6: =-Assumptions!B20*UnitEcon!B3/1000000 -> -117 | C6: =-Assumptions!C20*UnitEcon!C3/1000000 -> -122.7135 | D6: =-Assumptions!D20*UnitEcon!D3/1000000 -> -128.57208 | E6: =-Assumptions!E20*UnitEcon!E3/1000000 -> -134.57881 | F6: =-Assumptions!F20*UnitEcon!F3/1000000 -> -140.73681
A7: Investing Cash Flow | B7: =B6 -> -117 | C7: =C6 -> -122.7135 | D7: =D6 -> -128.57208 | E7: =E6 -> -134.57881 | F7: =F6 -> -140.73681
A8: Debt Issued/(Repaid) | B8: -200 | C8: =BS!C20-BS!B20 -> -200 | D8: =BS!D20-BS!C20 -> -200 | E8: =BS!E20-BS!D20 -> -200 | F8: =BS!F20-BS!E20 -> -200
A9: Dividends | B9: =-Assumptions!B22*IS!B20 -> -219.62341 | C9: =-Assumptions!C22*IS!C20 -> -238.58144 | D9: =-Assumptions!D22*IS!D20 -> -256.75373 | E9: =-Assumptions!E22*IS!E20 -> -273.72744 | F9: =-Assumptions!F22*IS!F20 -> -291.265
A10: Financing Cash Flow | B10: =B8+B9 -> -419.62341 | C10: =C8+C9 -> -438.58144 | D10: =D8+D9 -> -456.75373 | E10: =E8+E9 -> -473.72744 | F10: =F8+F9 -> -491.265
A11: Net Change in Cash | B11: =B5+B7+B10 -> 133.33186 | C11: =C5+C7+C10 -> 159.00687 | D11: =D5+D7+D10 -> 183.16729 | E11: =E5+E7+E10 -> 205.80149 | F11: =F5+F7+F10 -> 229.20235
A12: Opening Cash | B12: 866.66814 | C12: =B13 -> 1000 | D12: =C13 -> 1159.0069 | E12: =D13 -> 1342.1742 | F12: =E13 -> 1547.9756
A13: Closing Cash | B13: =B12+B11 -> 1000 | C13: =C12+C11 -> 1159.0069 | D13: =D12+D11 -> 1342.1742 | E13: =E12+E11 -> 1547.9756 | F13: =F12+F11 -> 1777.178
A14: Interest Paid (memo; in Net Income) | B14: =-IS!B17 -> -250 | C14: =-IS!C17 -> -240 | D14: =-IS!D17 -> -230 | E14: =-IS!E17 -> -220 | F14: =-IS!F17 -> -210

Sheet KPIs
A1: KEY QSR & FINANCIAL KPIs | B1: 2024 | C1: 2025 | D1: 2026 | E1: 2027 | F1: 2028
A2: GROWTH & UNITS
A3: System-Wide Sales ($M) | B3: =UnitEcon!B12 -> 26325 | C3: =UnitEcon!C12 -> 27655.071 | D3: =UnitEcon!D12 -> 28911.994 | E3: =UnitEcon!E12 -> 30079.315 | F3: =UnitEcon!F12 -> 31293.768
A4: System Sales Growth % | C4: =UnitEcon!C15 -> 0.050525 | D4: =UnitEcon!D15 -> 0.04545 | E4: =UnitEcon!E15 -> 0.040375 | F4: =UnitEcon!F15 -> 0.040375
A5: Total Units | B5: =UnitEcon!B3 -> 19500 | C5: =UnitEcon!C3 -> 19792.5 | D5: =UnitEcon!D3 -> 20089.388 | E5: =UnitEcon!E3 -> 20390.728 | F5: =UnitEcon!F3 -> 20696.589
A6: Net New Units | B6: =UnitEcon!B4 -> 288 | C6: =UnitEcon!C4 -> 292.5 | D6: =UnitEcon!D4 -> 296.8875 | E6: =UnitEcon!E4 -> 301.34081 | F6: =UnitEcon!F4 -> 305.86093
A7: Unit Growth % | C7: =UnitEcon!C3/UnitEcon!B3-1 -> 0.015 | D7: =UnitEcon!D3/UnitEcon!C3-1 -> 0.015 | E7: =UnitEcon!E3/UnitEcon!D3-1 -> 0.015 | F7: =UnitEcon!F3/UnitEcon!E3-1 -> 0.015
A8: % Franchised | B8: =UnitEcon!B9 -> 0.984615 | C8: =UnitEcon!C9 -> 0.986358 | D8: =UnitEcon!D9 -> 0.988053 | E8: =UnitEcon!E9 -> 0.989211 | F8: =UnitEcon!F9 -> 0.990337
A9: AUV - System ($M) | B9: =UnitEcon!B11 -> 1.35 | C9: =UnitEcon!C11 -> 1.39725 | D9: =UnitEcon!D11 -> 1.439167 | E9: =UnitEcon!E11 -> 1.475147 | F9: =UnitEcon!F11 -> 1.512025
A10: Same-Store Sales % | B10: =Assumptions!B3 -> 0.03 | C10: =Assumptions!C3 -> 0.035 | D10: =Assumptions!D3 -> 0.03 | E10: =Assumptions!E3 -> 0.025 | F10: =Assumptions!F3 -> 0.025
A11: PROFITABILITY
A12: Total Revenue ($M) | B12: =IS!B7 -> 1999.08 | C12: =IS!C7 -> 2054.843 | D12: =IS!D7 -> 2102.2457 | E12: =IS!E7 -> 2154.4514 | F12: =IS!F7 -> 2208.3739
A13: Revenue Growth % | C13: =IS!C7/IS!B7-1 -> 0.027894 | D13: =IS!D7/IS!C7-1 -> 0.023069 | E13: =IS!E7/IS!D7-1 -> 0.024833 | F13: =IS!F7/IS!E7-1 -> 0.025028
A14: Adjusted EBITDA ($M) | B14: =IS!B13 -> 1064.9556 | C14: =IS!C13 -> 1118.2951 | D14: =IS!D13 -> 1168.6466 | E14: =IS!E13 -> 1215.4931 | F14: =IS!F13 -> 1264.2271
A15: EBITDA Margin % | B15: =IS!B14 -> 0.532723 | C15: =IS!C14 -> 0.544224 | D15: =IS!D14 -> 0.555904 | E15: =IS!E14 -> 0.564178 | F15: =IS!F14 -> 0.57247
A16: Restaurant-Level Margin % | B16: =UnitEcon!B20 -> 0.18 | C16: =UnitEcon!C20 -> 0.18 | D16: =UnitEcon!D20 -> 0.18 | E16: =UnitEcon!E20 -> 0.18 | F16: =UnitEcon!F20 -> 0.18
A17: Net Income ($M) | B17: =IS!B20 -> 549.05853 | C17: =IS!C20 -> 596.4536 | D17: =IS!D20 -> 641.88433 | E17: =IS!E20 -> 684.31859 | F17: =IS!F20 -> 728.16251
A18: Net Margin % | B18: =IS!B20/IS!B7 -> 0.274656 | C18: =IS!C20/IS!C7 -> 0.290267 | D18: =IS!D20/IS!D7 -> 0.305333 | E18: =IS!E20/IS!E7 -> 0.31763 | F18: =IS!F20/IS!F7 -> 0.329728
A19: EPS ($) | B19: =IS!B21 -> 1.715808 | C19: =IS!C21 -> 1.863917 | D19: =IS!D21 -> 2.005889 | E19: =IS!E21 -> 2.138496 | F19: =IS!F21 -> 2.275508
A20: Royalty Revenue ($M) | B20: =IS!B4 -> 1166.4 | C20: =IS!C4 -> 1227.5016 | D20: =IS!D4 -> 1285.4967 | E20: =IS!E4 -> 1338.9652 | F20: =IS!F4 -> 1394.6113
A21: Effective Royalty Rate % | B21: =IS!B4/UnitEcon!B12 -> 0.044308 | C21: =IS!C4/UnitEcon!C12 -> 0.044386 | D21: =IS!D4/UnitEcon!D12 -> 0.044462 | E21: =IS!E4/UnitEcon!E12 -> 0.044514 | F21: =IS!F4/UnitEcon!F12 -> 0.044565
A22: RETURNS & EFFICIENCY
A23: ROE % | B23: =IS!B20/BS!B30 -> 0.145639 | C23: =IS!C20/BS!C30 -> 0.144494 | D23: =IS!D20/BS!D30 -> 0.14223 | E23: =IS!E20/BS!E30 -> 0.138987 | F23: =IS!F20/BS!F30 -> 0.135839
A24: ROA % | B24: =IS!B20/BS!B13 -> 0.050839 | C24: =IS!C20/BS!C13 -> 0.054402 | D24: =IS!D20/BS!D13 -> 0.057546 | E24: =IS!E20/BS!E13 -> 0.060183 | F24: =IS!F20/BS!F13 -> 0.0627
A25: ROIC % | B25: =IS!B16*(1-Assumptions!B18)/(BS!B17+BS!B20+BS!B30-BS!B3) -> 0.096082 | C25: =IS!C16*(1-Assumptions!C18)/(BS!C17+BS!C20+BS!C30-BS!C3) -> 0.10118 | D25: =IS!D16*(1-Assumptions!D18)/(BS!D17+BS!D20+BS!D30-BS!D3) -> 0.105984 | E25: =IS!E16*(1-Assumptions!E18)/(BS!E17+BS!E20+BS!E30-BS!E3) -> 0.11036 | F25: =IS!F16*(1-Assumptions!F18)/(BS!F17+BS!F20+BS!F30-BS!F3) -> 0.114869
A26: G&A % of System Sales | B26: =IS!B11/UnitEcon!B12 -> 0.009872 | C26: =IS!C11/UnitEcon!C12 -> 0.009659 | D26: =IS!D11/UnitEcon!D12 -> 0.009453 | E26: =IS!E11/UnitEcon!E12 -> 0.009311 | F26: =IS!F11/UnitEcon!F12 -> 0.009174
A27: CapEx ($M) | B27: =-CF!B6 -> 117 | C27: =-CF!C6 -> 122.7135 | D27: =-CF!D6 -> 128.57208 | E27: =-CF!E6 -> 134.57881 | F27: =-CF!F6 -> 140.73681
A28: CapEx % of Revenue | B28: =-CF!B6/IS!B7 -> 0.058527 | C28: =-CF!C6/IS!C7 -> 0.059719 | D28: =-CF!D6/IS!D7 -> 0.061159 | E28: =-CF!E6/IS!E7 -> 0.062465 | F28: =-CF!F6/IS!F7 -> 0.063729
A29: CASH & LEVERAGE
A30: Operating Cash Flow ($M) | B30: =CF!B5 -> 669.95528 | C30: =CF!C5 -> 720.30181 | D30: =CF!D5 -> 768.4931 | E30: =CF!E5 -> 814.10773 | F30: =CF!F5 -> 861.20416
A31: Free Cash Flow ($M) | B31: =CF!B5+CF!B6 -> 552.95528 | C31: =CF!C5+CF!C6 -> 597.58831 | D31: =CF!D5+CF!D6 -> 639.92102 | E31: =CF!E5+CF!E6 -> 679.52892 | F31: =CF!F5+CF!F6 -> 720.46736
A32: FCF Conversion % (FCF/EBITDA) | B32: =(CF!B5+CF!B6)/IS!B13 -> 0.519228 | C32: =(CF!C5+CF!C6)/IS!C13 -> 0.534374 | D32: =(CF!D5+CF!D6)/IS!D13 -> 0.547574 | E32: =(CF!E5+CF!E6)/IS!E13 -> 0.559056 | F32: =(CF!F5+CF!F6)/IS!F13 -> 0.569888
A33: Total Debt ($M) | B33: =BS!B17+BS!B20 -> 5000 | C33: =BS!C17+BS!C20 -> 4800 | D33: =BS!D17+BS!D20 -> 4600 | E33: =BS!E17+BS!E20 -> 4400 | F33: =BS!F17+BS!F20 -> 4200
A34: Net Debt ($M) | B34: =BS!B17+BS!B20-BS!B3 -> 4000 | C34: =BS!C17+BS!C20-BS!C3 -> 3640.9931 | D34: =BS!D17+BS!D20-BS!D3 -> 3257.8258 | E34: =BS!E17+BS!E20-BS!E3 -> 2852.0244 | F34: =BS!F17+BS!F20-BS!F3 -> 2422.822
A35: Debt / EBITDA (x) | B35: =(BS!B17+BS!B20)/IS!B13 -> 4.695031 | C35: =(BS!C17+BS!C20)/IS!C13 -> 4.292248 | D35: =(BS!D17+BS!D20)/IS!D13 -> 3.936177 | E35: =(BS!E17+BS!E20)/IS!E13 -> 3.61993 | F35: =(BS!F17+BS!F20)/IS!F13 -> 3.322188
A36: Net Debt / EBITDA (x) | B36: =(BS!B17+BS!B20-BS!B3)/IS!B13 -> 3.756025 | C36: =(BS!C17+BS!C20-BS!C3)/IS!C13 -> 3.255843 | D36: =(BS!D17+BS!D20-BS!D3)/IS!D13 -> 2.787691 | E36: =(BS!E17+BS!E20-BS!E3)/IS!E13 -> 2.346393 | F36: =(BS!F17+BS!F20-BS!F3)/IS!F13 -> 1.916445
A37: Interest Coverage (x) | B37: =IS!B16/IS!B17 -> 3.780043 | C37: =IS!C16/IS!C17 -> 4.145852 | D37: =IS!D16/IS!D17 -> 4.53266 | E37: =IS!E16/IS!E17 -> 4.937391 | F37: =IS!F16/IS!F17 -> 5.389165
A38: Dividends ($M) | B38: =-CF!B9 -> 219.62341 | C38: =-CF!C9 -> 238.58144 | D38: =-CF!D9 -> 256.75373 | E38: =-CF!E9 -> 273.72744 | F38: =-CF!F9 -> 291.265
A39: Dividend Payout % | B39: =-CF!B9/IS!B20 -> 0.4 | C39: =-CF!C9/IS!C20 -> 0.4 | D39: =-CF!D9/IS!D20 -> 0.4 | E39: =-CF!E9/IS!E20 -> 0.4 | F39: =-CF!F9/IS!F20 -> 0.4
A40: Dividend per Share ($) | B40: =-CF!B9/Assumptions!B23 -> 0.686323 | C40: =-CF!C9/Assumptions!C23 -> 0.745567 | D40: =-CF!D9/Assumptions!D23 -> 0.802355 | E40: =-CF!E9/Assumptions!E23 -> 0.855398 | F40: =-CF!F9/Assumptions!F23 -> 0.910203
